Workbook
Name Excel_BuiltIn_Print_Area_1_1: #REF!
Name Excel_BuiltIn_Print_Area_1_1: Proposta!$A$2:$K$74
Name Excel_BuiltIn_Print_Area_2: #REF!
Name Excel_BuiltIn_Print_Area_2: Proposta!$A$2:$L$74
Name Excel_BuiltIn_Print_Area_2_1: #REF!
Name Excel_BuiltIn_Print_Area_2_1: Proposta!$A$2:$G$74
Name Selecionar1: Proposta!$P$8
Name Selecionar2: Proposta!$P$6
Name Selecionar3: Proposta!$P$10
Name Selecionar4: Proposta!$Q$14
Name Selecionar5: Proposta!$O$6
Name Selecionar6: #REF!
Name Selecionar7: #REF!
Name Selecionar8: Proposta!$M$12

Sheet Proposta
C1: PROPOSTA DE COMPRA DE IMÓVEL | G1: Fone: (62) 3998-1086 Avenida Milão, 1359, Qd. CP O5, Lt. 19/20, Sl. 1,2,3, Setor Residencial Celina Park Goiânia /GO, CEP: 74.367-635 CJ.29886 www.mybrokerimoveis.com.br
A2: DADOS DO(S) ADQUIRENTE(S)
A4: 1ºPROPONENTE:
A5: NACIONALIDADE: | D5: NATURALIDADE: | G5: NASCIMENTO: | M5: CASADO(A) | N5: COMUNHÃO UNIVERSAL DE BENS
A6: RG/ÓRGÃO EMISSOR: | D6: DATA EMISSÃO: | G6: CPF: | M6: CONVIVENTE | N6: COMUNHÃO PARCIAL DE BENS
A7: ESTADO CIVIL: | D7: REGIME DE COMUNHÃO: | G7: DATA CASAM.: | M7: DIVORCIADO(A) | N7: SEPARAÇÃO DE BENS
A8: FILIAÇÃO: | M8: SEPARADO(A) | N8: PARTICIPAÇÃO FINAL NOS AQUESTOS
A9: ENDEREÇO: | G9: CEP: | M9: SOLTEIRO(A) | N9: COMUNHÃO DE BENS (regime único antes de 1977)
A10: FONE RESID.: | D10: FONE COMERCIAL: | G10: CELULAR: | M10: VIUVO(A)
A11: PROFISSÃO: | D11: CARGO: | G11: E-MAIL:
A12: EMPRESA: | G12: RENDA:
A14: | | CÔNJUGE | D14: | | SEGUNDO PROPONENTE | G14: | | PROCURADOR
M15: ALIANÇA
A16: 2º PROPONENTE: | M16: ALPHAVILLE
A17: NACIONALIDADE: | D17: NATURALIDADE: | G17: NASCIMENTO: | M17: ARTE
A18: RG/ÓRGÃO EMISSOR: | D18: DATA EMISSÃO: | G18: CPF: | M18: ÁTILA
A19: ESTADO CIVIL: | D19: REGIME DE COMUNHÃO: | G19: DATA CASAM.: | M19: BAMBUÍ
A20: FILIAÇÃO: | M20: BORGES LANDEIRO
A21: ENDEREÇO: | G21: CEP: | M21: BRASAL
A22: FONE RESID.: | D22: FONE COMERCIAL: | G22: CELULAR: | M22: BROOKFIELD
A23: PROFISSÃO: | D23: CARGO: | G23: E-MAIL: | M23: CAMPOS
A24: EMPRESA: | G24: RENDA: | M24: CANADÁ
M25: CITY
A26: SOBRE O IMÓVEL | M26: CMC
M27: CMO
A28: EMPREENDIMENTO: | E28: UNIDADE / TORRE: | G28: QUADRA / LOTE: | M28: CONSCIENTE
M29: DINÂMICA
A30: BOX(S) / LOCAL: | D30: ESCANINHO / LOCAL: | F30: INCORPORADOR / CONSTRUTOR: | M30: EBM
M31: ELMO ENGENHARIA
A32: PREÇO E FORMA DE PAGAMENTO | M32: ENEC
A33: Número de Parcelas | B33: Periodicidade | C33: Data do 1° Vencimento da Serie | D33: Valor Unitário Nesta Data | E33: Valor Total da Serie de Parcelas | F33: Atualização Monetária | G33: Observações / Forma de Pagamento | M33: ENGEL
D34: 0 | E34: =D34*A34 -> 0
D35: 0 | E35: =D35*A35 -> 0 | M35: ENGESEG
D36: 0 | E36: =D36*A36 -> 0 | M36: EUROAMÉRICA
D37: 0 | E37: =D37*A37 -> 0 | M37: FGR
D38: 0 | E38: =D38*A38 -> 0 | M38: FLAMBOYANT URBANISMO
D39: 0 | E39: =D39*A39 -> 0 | M39: FR
D40: 0 | E40: =D40*A40 -> 0 | M40: GMS
D41: 0 | E41: =D41*A41 -> 0 | M41: GOVESA
D42: 0 | E42: =D42*A42 -> 0 | M42: GPL
...

Sheet Intermediacao
A5: INSTRUMENTO PARTICULAR DE INTERMEDIAÇÃO DO CONTRATO PARTICULAR DE PROMESSA DE COMPRA E VENDA DE UNIDADE IMOBILIÁRIA
A8: Entre partes, de um lado na qualidade de INTERMEDIADORA, doravante designado como CONTRATADA: ELDORADO BROKER GESTÃO IMOBILIÁRIA LTDA pessoa jurídica de direito privado, inscrita no CNPJ sob nº 41.756.564/0001-36, com sede na Avenida Milão, 1359, Qd. CP O5, Lt. 19/20, Sl. 1,2,3, Setor Residencial Celina Park Goiânia /GO, CEP: 74.367-635, e de outro lado, na qualidade de:
A12: CONTRATANTE (S)
A13: 1º Proponente: | C13: =Proposta!B4 -> 0
A14: CPF: | B14: =Proposta!H6 -> 0 | F14: CEP: | G14: =Proposta!H9 -> 0
A15: Endereço: | B15: =Proposta!B9 -> 0
A16: Profissão: | B16: =Proposta!B11 -> 0 | F16: Estado Civil: | G16: =Proposta!B7 -> 0
A17: Celular: | B17: =SUM(Proposta!H10) -> 0 | F17: E-mail: | G17: =Proposta!H11 -> 0
A19: 2º Proponente: | C19: =Proposta!B16 -> 0
A20: CPF: | B20: =Proposta!H18 -> 0 | F20: CEP: | G20: =Proposta!H21 -> 0
A21: Endereço: | B21: =Proposta!B21 -> 0
A22: Profissão: | B22: =Proposta!B23 -> 0 | F22: Estado Civil: | G22: =Proposta!B19 -> 0
A23: Celular: | B23: =Proposta!H22 -> 0 | F23: E-mail: | G23: =Proposta!H23 -> 0
A25: CONDIÇÕES GERAIS
A26: Assina(m) o presente INSTRUMENTO PARTICULAR DE INTERMEDIAÇÃO DO CONTRATO PARTICULAR DE PROMESSA DE COMPRA E VENDA DE UNIDADE IMOBILIÁRIA, que reger-se-á pelas cláusulas e condições que mutuamente outorgam, aceitam e se obrigam a cumprir e respeitar, por si, seus herdeiros e sucessores, na forma da Lei, a contratação dos serviços profissionais da CONTRATADA para a aquisição da unidade abaixo descrita, regendo-se nos seguintes termos: CLÁUSULA PRIMEIRA – O(s) CONTRATANTE(S) por intermédio da CONTRATADA, promete(m) adquirir o seguinte:
A33: Empreendimento: | C33: =Proposta!B28 -> 0
A34: Unidade: | B34: =Proposta!F28 -> 0 | E34: Quadra/Lote | G34: =Proposta!H28 -> 0 | H34: Valor Total: | I34: =Proposta!E56 -> 0
A35: CLÁUSULA SEGUNDA – O(s) CONTRATANTE(S), em função da intermediação havida para a aquisição da unidade comercial descrita na Cláusula 1ª, pagará(ão), neste ato, à CONTRATADA, a quantia total de
A37: =Proposta!E54 -> 0 | C37: =Proposta!E58 -> 0
A38: referente à PRESTAÇÃO DE SERVIÇOS DE INTERMEDIAÇÃO IMOBILIÁRIA (CORRETAGEM e PRÊMIO).
A39: PARÁGRAFO PRIMEIRO: O(s) CONTRATANTE(S) deverá(ão) efetuar(em) o(s) pagamento(s) da(s) seguinte(s) forma(s):
B41: N°de Parcela | C41: Forma de Pagamento | E41: Valor | G41: Vencimento
A49: 1º CONTRATANTE 2º CONTRATANTE ELDORADO BROKER GESTAO MOBILIÁRIA LTDA
A54: Sendo tais valores pagos diretamente pelo (a)(s) CONTRATANTE(S) a título do serviço prestado pela CONTRATADA, da seguinte forma:
A57: CARGO | C57: NOME COMPLETO | G57: CRECI | H57: Comissão % | I57: Comissão R$
A58: CORRETOR | C58: =Proposta!B71 -> 0 | G58: =Proposta!D71 -> 0 | H58: 0.3 | I58: =$A$37*H58 -> 0
A59: GERENTE | C59: =Proposta!F71 -> 0 | G59: =Proposta!I71 -> 0 | H59: 0.14 | I59: =$A$37*H59 -> 0
A60: DIRETOR DE VENDA | C60: SANDRI GARCIA OLIVEIRA | G60: 24782 | H60: 0.05 | I60: =$A$37*H60 -> 0
A61: DIRETOR DE VENDA | C61: RICARDO AUGUSTO | G61: 10102 | H61: 0.05 | I61: =$A$37*H61 -> 0
A62: COORDENADOR
A63: MY BROKER | C63: ELDORADO BROKER GESTAO MOBILIÁRIA LTDA | G63: 29886 | H63: 0.46 | I63: =$A$37*H63 -> 0
A65: PARÁGRAFO SEGUNDO: Os valores e forma de pagamento descritos acima serão cumpridos de modo direto entre o (a)(s) CONTRATANTE (S) e cada sujeito favorecido na tabela retro mencionada, uma vez que os mesmos são associados da CONTRATADA e fazem jus ao recebimento dos valores a eles atribuídos. CLÁUSULA TERCEIRA – Sendo feito o pagamento na forma parcelada da taxa de intermediação imobiliária, considera-se estipulado o prazo máximo de tolerância de 3 (três) dias corridos da data que a devida parcela mensal vencer. Caso qualquer um dos pagamentos estiverem em atraso por mais de 10 (dez) dias, sem necessidade de prévia notificação, o presente termo será executado no valor total inadimplente – independente de existência de parcelas vencidas, sendo consideradas todas as futuras como vencidas de forma antecipada. PARÁGRAFO PRIMEIRO: Caso o(s) CONTRATANTE(S) realizem os pagamentos parcelados por boletos bancários, desde já anuem a emissão das duplicatas virtuais. PARÁGRAFO SEGUNDO: Desde já o(s) CONTRATANTE(S) ficam ciente(s) que, após o 10º (décimo) dia de atraso, estará(ão) sujeito(s) à negativação do presente débito junto ao SPC/SERASA – sem a necessidade de prévia notificação, além das medidas judiciais que forem pertinentes a qualquer tempo. CLÁUSULA QUARTA – O(s) CONTRATANTE(S) reconhece(m), expressamente, que os serviços de intermediação ora contratados são oriundos de uma relação comercial entre este(s) o(s) CONTRATANTE(S) e a CONTRATADA, não cabendo a empresa responsável pelo empreendimento interferir por qualquer questão no presente contrato. CLÁUSULA QUINTA – O(s) CONTRATANTE(S) reconhece(m), expressamente, que por se tratarem de serviços já prestados pela CONTRATADA na forma e condições da cláusula segunda, e de acordo com sua própria característica, não são passíveis de impugnação a qualquer título e muito menos sujeitos a qualquer devolução, tendo como termo irrevogável e irretratável. PARÁGRAFO ÚNICO: Caso o(s) CONTRATANTE(S) efetive(m) a rescisão do CONTRATO PARTICULAR DE PROMESSA DE COMPRA E VENDA DA UNIDADE IMOBILIÁRIA junto a empresa responsável pelo empreendimento, a remuneração da corretagem continua sendo devida – nos termos do artigo 725 do Código Civil. CLÁUSULA SEXTA – Caso o(s) CONTRATANTE(S) não efetue(m) o pagamento da(s) parcela(s) referente à taxa de intermediação conforme estipulado na Cláusula Segunda – parágrafo único, serão acrescidos, correção monetária sob índice INPC-IBGE pro rata, multa de 10% e juros de 1% ao mês, bem como, honorários advocatícios na forma seguinte: PARÁGRAFO ÚNICO: A base de 20% (vinte por cento) sobre o valor total do débito apurado em caso de propositura de medidas judiciais necessárias. CLÁUSULA SÉTIMA – O presente contrato é celebrado por mútuas e recíprocas vontades na condição expressa de irrevogabilidade e irretratabilidade, obrigando as partes e seus herdeiros e sucessores a qualquer título.
A104: 1º CONTRATANTE 2º CONTRATANTE ELDORADO BROKER GESTAO MOBILIÁRIA LTDA
A110: CLÁUSULA OITAVA – Nos termos definidos neste instrumento, cujas obrigações estão claras e definidas, constitui-se o presente documento assinado por duas testemunhas extrajudicial como título executivo (artigos 586 e 784, III do CPC) – que a partir da assinatura das partes torna-se plenamente eficaz e válido nos moldes legais estabelecidos. CLÁUSULA NONA – O(s) CONTRATANTE(S) declara(m), expressamente, que leram atentamente todas as cláusulas e condições aqui pactuadas, notadamente a parte do preço e condições de pagamento, estando, portanto, em concordância com a plenitude das avenças. CLÁUSULA DÉCIMA – O foro competente para solucionar possíveis questionamentos jurídicos e/ou para a devida execução do presente termo de acordo, será na comarca de Goiânia – Goiás.
A119: E, por as partes estarem assim justas e contratadas, assinam o presente em duas vias de igual teor juntamente na presença de duas testemunhas que subscrevem.
H122: Goiânia-GO, | I122: =Proposta!C74 -> 44858
A125: 1º PROPONENTE | C125: =Proposta!B4 -> 0
A129: 2º PROPONENTE | C129: =Proposta!B16 -> 0
A133: CORRETOR | C133: =Proposta!B71 -> 0
A137: GERENTE | C137: =Proposta!F71 -> 0
...

Sheet Bordero Lancamento
A1: FORMULÁRIO DE VENDA AG ELDORADO
A2: CLIENTE COMPRADOR | B2: =Intermediacao!C13 -> 0
A3: GERENTE | B3: =Proposta!F71 -> 0
A4: CORRETOR | B4: =Proposta!B71 -> 0
A5: MÊS DE REFERÊNCIA
A7: DADOS DA VENDA
A8: LANCAMENTO | B8: X
A10: RAZÃO SOCIAL CONSTRUTORA:
A11: EMPREENDIMENTO: | B11: =Intermediacao!C33 -> 0
A12: UNIDADE - TORRE QD - LT
A13: DATA DO CONTRATO: | B13: =Intermediacao!I122 -> 44858
A14: VALOR DA VENDA - VGV | B14: =Intermediacao!I34 -> 0
A15: COMISSAO | B15: =Intermediacao!A37 -> 0
A16: PREMIACAO
A17: TOTAL DA INTERMEDIACAO | B17: =B15+B16 -> 0
A19: FLUXO DE PAGAMENTO
B20: 1º PARC | C20: 2º PARC | D20: 3º PARC | E20: 4º PARC
A21: FORMA DE PAGAMENTO
A22: VALOR
A23: VENCIMENTO
B25: NOMES | D25: (%) COMISSÃO | E25: R$ COMISSAO | F25: PREMIACAO | G25: TOTAL | H25: =B20 -> 1º PARC | I25: =C20 -> 2º PARC | J25: =D20 -> 3º PARC | K25: =E20 -> 4º PARC
A26: CORRETOR | D26: 0.3 | E26: =$B$15*D26 -> 0 | F26: =B16*60% -> 0 | G26: =E26+F26 -> 0
A27: GERENTE | D27: 0.14 | E27: =$B$15*D27 -> 0 | F27: =B16*20% -> 0 | G27: =E27+F27 -> 0
A28: COORDENADOR | F28: 0 | G28: =E28+F28 -> 0
A29: DIRETORIA AG | B29: SANDRI GARCIA OLIVEIRA | D29: 0.05 | E29: =$B$15*D29 -> 0 | F29: =B16*5% -> 0 | G29: =E29+F29 -> 0
A30: DIRETORIA AG | B30: RICARDO AUGUSTO | D30: 0.05 | E30: =$B$15*D30 -> 0 | F30: =B16*5% -> 0 | G30: =E30+F30 -> 0
A31: MY BROKER | B31: AG ELDORADO | D31: 0.46 | E31: =$B$15*D31 -> 0 | F31: =B16*10% -> 0 | G31: =E31+F31 -> 0
A32: TOTAL | D32: =SUM(D26:D31) -> 1 | E32: =SUM(E26:E31) -> 0 | F32: =SUM(F26:F31) -> 0 | G32: =SUM(G26:G31) -> 0 | H32: =SUM(H26:H31) -> 0 | I32: =SUM(I26:I31) -> 0 | J32: =SUM(J26:J31) -> 0 | K32: =SUM(K26:K31) -> 0

Sheet FLUXO
D2: FLUXO DE PAGAMENTO
B3: PARCELAMENTO - ATO + 2 X | D3: PARCELAMENTO - ATO + 3X | F3: PARCELAMENTO - ATO + 4X | H3: PARCELAMENTO ATO + 5X
B4: CORRETOR | C4: 2X | D4: CORRETOR | E4: 3X | F4: CORRETOR | G4: 4 X | H4: CORRETOR | I4: 5X OU MAIS
B5: GERENTE | C5: 1X | D5: GERENTE | E5: 2X | F5: GERENTE | G5: 3X | H5: GERENTE | I5: 4X
B6: COORDENADOR | C6: 1X | D6: COORDENADOR | E6: 1X | F6: COORDENADOR | G6: 1X | H6: COORDENADOR | I6: 1X
B7: DIRETOR DA VENDA | C7: 1X | D7: DIRETOR DA VENDA | E7: 1X | F7: DIRETOR DA VENDA | G7: 2X | H7: DIRETOR DA VENDA | I7: 3X
B8: IMOBILIARIA | C8: 2X | D8: IMOBILIARIA | E8: 3X | F8: IMOBILIARIA | G8: 4 X | H8: IMOBILIARIA | I8: MAXIMO EM 6X
H9: NECESSÁRIO APROVAÇÃO DO ALBUQUERQUE
